<?xml version="1.0" encoding="UTF-8"?>
<testng-results retried="1" ignored="1" total="3" passed="0" failed="1" skipped="0">
  <reporter-output>
  </reporter-output>
  <suite started-at="2025-01-06T22:56:49 IST" name="MyTestSuite" finished-at="2025-01-06T22:57:06 IST" duration-ms="17528">
    <groups>
      <group name="Regression">
        <method signature="ErrorValidations.loginErrorValidation()[pri:0, instance:rahulshettyacademy.Tests.ErrorValidations@7b94089b]" name="loginErrorValidation" class="rahulshettyacademy.Tests.ErrorValidations"/>
      </group> <!-- Regression -->
    </groups>
    <test started-at="2025-01-06T22:56:49 IST" name="Submit Order Test" finished-at="2025-01-06T22:56:49 IST" duration-ms="8">
    </test> <!-- Submit Order Test -->
    <test started-at="2025-01-06T22:56:49 IST" name="Error Validations Test" finished-at="2025-01-06T22:57:06 IST" duration-ms="17528">
      <class name="rahulshettyacademy.Tests.ErrorValidations">
        <test-method is-config="true" signature="launchApplication()[pri:0, instance:rahulshettyacademy.Tests.ErrorValidations@7b94089b]" started-at="2025-01-06T22:56:49 IST" name="launchApplication" finished-at="2025-01-06T22:56:57 IST" duration-ms="8031" status="PASS">
          <reporter-output>
          </reporter-output>
        </test-method> <!-- launchApplication -->
        <test-method retried="true" signature="loginErrorValidation()[pri:0, instance:rahulshettyacademy.Tests.ErrorValidations@7b94089b]" started-at="2025-01-06T22:56:57 IST" name="loginErrorValidation" finished-at="2025-01-06T22:56:58 IST" duration-ms="669" status="SKIP">
          <exception class="java.lang.AssertionError">
            <message>
              <![CDATA[expected [Incorrect email or password.] but found [Incorrect email or password..]]]>
            </message>
            <full-stacktrace>
              <![CDATA[java.lang.AssertionError: expected [Incorrect email or password.] but found [Incorrect email or password..]
at org.testng.Assert.fail(Assert.java:99)
at org.testng.Assert.failNotEquals(Assert.java:1037)
at org.testng.Assert.assertEqualsImpl(Assert.java:140)
at org.testng.Assert.assertEquals(Assert.java:122)
at org.testng.Assert.assertEquals(Assert.java:629)
at org.testng.Assert.assertEquals(Assert.java:639)
at rahulshettyacademy.Tests.ErrorValidations.loginErrorValidation(ErrorValidations.java:21)
at java.base/jdk.internal.reflect.DirectMethodHandleAccessor.invoke(DirectMethodHandleAccessor.java:103)
at java.base/java.lang.reflect.Method.invoke(Method.java:580)
at org.testng.internal.MethodInvocationHelper.invokeMethod(MethodInvocationHelper.java:133)
at org.testng.internal.TestInvoker.invokeMethod(TestInvoker.java:598)
at org.testng.internal.TestInvoker.invokeTestMethod(TestInvoker.java:173)
at org.testng.internal.MethodRunner.runInSequence(MethodRunner.java:46)
at org.testng.internal.TestInvoker$MethodInvocationAgent.invoke(TestInvoker.java:824)
at org.testng.internal.TestInvoker.invokeTestMethods(TestInvoker.java:146)
at org.testng.internal.TestMethodWorker.invokeTestMethods(TestMethodWorker.java:146)
at org.testng.internal.TestMethodWorker.run(TestMethodWorker.java:128)
at java.base/java.util.ArrayList.forEach(ArrayList.java:1596)
at org.testng.TestRunner.privateRun(TestRunner.java:794)
at org.testng.TestRunner.run(TestRunner.java:596)
at org.testng.SuiteRunner.runTest(SuiteRunner.java:377)
at org.testng.SuiteRunner.access$000(SuiteRunner.java:28)
at org.testng.SuiteRunner$SuiteWorker.run(SuiteRunner.java:418)
at org.testng.internal.thread.ThreadUtil.lambda$execute$0(ThreadUtil.java:64)
at java.base/java.util.concurrent.FutureTask.run(FutureTask.java:317)
at java.base/java.util.concurrent.ThreadPoolExecutor.runWorker(ThreadPoolExecutor.java:1144)
at java.base/java.util.concurrent.ThreadPoolExecutor$Worker.run(ThreadPoolExecutor.java:642)
at java.base/java.lang.Thread.run(Thread.java:1583)
]]>
            </full-stacktrace>
          </exception> <!-- java.lang.AssertionError -->
          <reporter-output>
          </reporter-output>
        </test-method> <!-- loginErrorValidation -->
        <test-method is-config="true" signature="tearDown()[pri:0, instance:rahulshettyacademy.Tests.ErrorValidations@7b94089b]" started-at="2025-01-06T22:56:58 IST" name="tearDown" finished-at="2025-01-06T22:56:58 IST" duration-ms="236" status="PASS">
          <reporter-output>
          </reporter-output>
        </test-method> <!-- tearDown -->
        <test-method is-config="true" signature="launchApplication()[pri:0, instance:rahulshettyacademy.Tests.ErrorValidations@7b94089b]" started-at="2025-01-06T22:56:58 IST" name="launchApplication" finished-at="2025-01-06T22:57:05 IST" duration-ms="7338" status="PASS">
          <reporter-output>
          </reporter-output>
        </test-method> <!-- launchApplication -->
        <test-method signature="loginErrorValidation()[pri:0, instance:rahulshettyacademy.Tests.ErrorValidations@7b94089b]" started-at="2025-01-06T22:57:05 IST" name="loginErrorValidation" finished-at="2025-01-06T22:57:06 IST" duration-ms="586" status="FAIL">
          <exception class="java.lang.AssertionError">
            <message>
              <![CDATA[expected [Incorrect email or password.] but found [Incorrect email or password..]]]>
            </message>
            <full-stacktrace>
              <![CDATA[java.lang.AssertionError: expected [Incorrect email or password.] but found [Incorrect email or password..]
at org.testng.Assert.fail(Assert.java:99)
at org.testng.Assert.failNotEquals(Assert.java:1037)
at org.testng.Assert.assertEqualsImpl(Assert.java:140)
at org.testng.Assert.assertEquals(Assert.java:122)
at org.testng.Assert.assertEquals(Assert.java:629)
at org.testng.Assert.assertEquals(Assert.java:639)
at rahulshettyacademy.Tests.ErrorValidations.loginErrorValidation(ErrorValidations.java:21)
at java.base/jdk.internal.reflect.DirectMethodHandleAccessor.invoke(DirectMethodHandleAccessor.java:103)
at java.base/java.lang.reflect.Method.invoke(Method.java:580)
at org.testng.internal.MethodInvocationHelper.invokeMethod(MethodInvocationHelper.java:133)
at org.testng.internal.TestInvoker.invokeMethod(TestInvoker.java:598)
at org.testng.internal.TestInvoker.retryFailed(TestInvoker.java:213)
at org.testng.internal.MethodRunner.runInSequence(MethodRunner.java:58)
at org.testng.internal.TestInvoker$MethodInvocationAgent.invoke(TestInvoker.java:824)
at org.testng.internal.TestInvoker.invokeTestMethods(TestInvoker.java:146)
at org.testng.internal.TestMethodWorker.invokeTestMethods(TestMethodWorker.java:146)
at org.testng.internal.TestMethodWorker.run(TestMethodWorker.java:128)
at java.base/java.util.ArrayList.forEach(ArrayList.java:1596)
at org.testng.TestRunner.privateRun(TestRunner.java:794)
at org.testng.TestRunner.run(TestRunner.java:596)
at org.testng.SuiteRunner.runTest(SuiteRunner.java:377)
at org.testng.SuiteRunner.access$000(SuiteRunner.java:28)
at org.testng.SuiteRunner$SuiteWorker.run(SuiteRunner.java:418)
at org.testng.internal.thread.ThreadUtil.lambda$execute$0(ThreadUtil.java:64)
at java.base/java.util.concurrent.FutureTask.run(FutureTask.java:317)
at java.base/java.util.concurrent.ThreadPoolExecutor.runWorker(ThreadPoolExecutor.java:1144)
at java.base/java.util.concurrent.ThreadPoolExecutor$Worker.run(ThreadPoolExecutor.java:642)
at java.base/java.lang.Thread.run(Thread.java:1583)
]]>
            </full-stacktrace>
          </exception> <!-- java.lang.AssertionError -->
          <reporter-output>
          </reporter-output>
        </test-method> <!-- loginErrorValidation -->
        <test-method is-config="true" signature="tearDown()[pri:0, instance:rahulshettyacademy.Tests.ErrorValidations@7b94089b]" started-at="2025-01-06T22:57:06 IST" name="tearDown" finished-at="2025-01-06T22:57:06 IST" duration-ms="269" status="PASS">
          <reporter-output>
          </reporter-output>
        </test-method> <!-- tearDown -->
      </class> <!-- rahulshettyacademy.Tests.ErrorValidations -->
    </test> <!-- Error Validations Test -->
  </suite> <!-- MyTestSuite -->
</testng-results>
